2021-08-24 12:17:31,801 - octolapse.__init__ - INFO - Started logging to file.
2021-08-24 12:17:31,806 - octolapse.settings - INFO - Loading existing settings file from: /home/pi/.octoprint/data/octolapse/settings.json.
2021-08-24 12:17:31,832 - octolapse.settings - INFO - Creating settings from iterable.
2021-08-24 12:17:31,893 - octolapse.settings - INFO - Settings created from iterable.
2021-08-24 12:17:31,894 - octolapse.settings - INFO - Settings file loaded.
2021-08-24 12:17:32,150 - octolapse.settings_external - ERROR - Could not retrieve the settings file from the server!  Using cached version.
Traceback (most recent call last):
  File "/home/pi/oprint/lib/python3.7/site-packages/urllib3/connection.py", line 170, in _new_conn
    (self._dns_host, self.port), self.timeout, **extra_kw
  File "/home/pi/oprint/lib/python3.7/site-packages/urllib3/util/connection.py", line 73, in create_connection
    for res in socket.getaddrinfo(host, port, family, socket.SOCK_STREAM):
  File "/usr/lib/python3.7/socket.py", line 748, in getaddrinfo
    for res in _socket.getaddrinfo(host, port, family, type, proto, flags):
socket.gaierror: [Errno -3] Temporary failure in name resolution

During handling of the above exception, another exception occurred:

Traceback (most recent call last):
  File "/home/pi/oprint/lib/python3.7/site-packages/urllib3/connectionpool.py", line 706, in urlopen
    chunked=chunked,
  File "/home/pi/oprint/lib/python3.7/site-packages/urllib3/connectionpool.py", line 382, in _make_request
    self._validate_conn(conn)
  File "/home/pi/oprint/lib/python3.7/site-packages/urllib3/connectionpool.py", line 1010, in _validate_conn
    conn.connect()
  File "/home/pi/oprint/lib/python3.7/site-packages/urllib3/connection.py", line 353, in connect
    conn = self._new_conn()
  File "/home/pi/oprint/lib/python3.7/site-packages/urllib3/connection.py", line 182, in _new_conn
    self, "Failed to establish a new connection: %s" % e
urllib3.exceptions.NewConnectionError: <urllib3.connection.HTTPSConnection object at 0x69c937b0>: Failed to establish a new connection: [Errno -3] Temporary failure in name resolution

During handling of the above exception, another exception occurred:

Traceback (most recent call last):
  File "/home/pi/oprint/lib/python3.7/site-packages/requests/adapters.py", line 449, in send
    timeout=timeout
  File "/home/pi/oprint/lib/python3.7/site-packages/urllib3/connectionpool.py", line 756, in urlopen
    method, url, error=e, _pool=self, _stacktrace=sys.exc_info()[2]
  File "/home/pi/oprint/lib/python3.7/site-packages/urllib3/util/retry.py", line 573, in increment
    raise MaxRetryError(_pool, url, error or ResponseError(cause))
urllib3.exceptions.MaxRetryError: HTTPSConnectionPool(host='raw.githubusercontent.com', port=443): Max retries exceeded with url: /FormerLurker/Octolapse-Profiles/master/versions.json?nonce=2377b8fbc7394ae3ac074fa919df07f4 (Caused by NewConnectionError('<urllib3.connection.HTTPSConnection object at 0x69c937b0>: Failed to establish a new connection: [Errno -3] Temporary failure in name resolution'))

During handling of the above exception, another exception occurred:

Traceback (most recent call last):
  File "/home/pi/oprint/lib/python3.7/site-packages/octoprint_octolapse/settings_external.py", line 250, in _get_versions
    timeout=float(10)
  File "/home/pi/oprint/lib/python3.7/site-packages/requests/api.py", line 76, in get
    return request('get', url, params=params, **kwargs)
  File "/home/pi/oprint/lib/python3.7/site-packages/requests/api.py", line 61, in request
    return session.request(method=method, url=url, **kwargs)
  File "/home/pi/oprint/lib/python3.7/site-packages/requests/sessions.py", line 542, in request
    resp = self.send(prep, **send_kwargs)
  File "/home/pi/oprint/lib/python3.7/site-packages/requests/sessions.py", line 655, in send
    r = adapter.send(request, **kwargs)
  File "/home/pi/oprint/lib/python3.7/site-packages/requests/adapters.py", line 516, in send
    raise ConnectionError(e, request=request)
requests.exceptions.ConnectionError: HTTPSConnectionPool(host='raw.githubusercontent.com', port=443): Max retries exceeded with url: /FormerLurker/Octolapse-Profiles/master/versions.json?nonce=2377b8fbc7394ae3ac074fa919df07f4 (Caused by NewConnectionError('<urllib3.connection.HTTPSConnection object at 0x69c937b0>: Failed to establish a new connection: [Errno -3] Temporary failure in name resolution'))

During handling of the above exception, another exception occurred:

Traceback (most recent call last):
  File "/home/pi/oprint/lib/python3.7/site-packages/octoprint_octolapse/settings_external.py", line 43, in get_available_profiles
    profiles_dict = ExternalSettings._get_profiles_from_server(current_octolapse_version)
  File "/home/pi/oprint/lib/python3.7/site-packages/octoprint_octolapse/settings_external.py", line 83, in _get_profiles_from_server
    settings_version = ExternalSettings._get_best_settings_version(current_octolapse_version)
  File "/home/pi/oprint/lib/python3.7/site-packages/octoprint_octolapse/settings_external.py", line 217, in _get_best_settings_version
    versions = ExternalSettings._get_versions()["versions"]
  File "/home/pi/oprint/lib/python3.7/site-packages/octoprint_octolapse/settings_external.py", line 260, in _get_versions
    raise ExternalSettingsError('profiles-retrieval-error', message, cause=e)
octoprint_octolapse.settings_external.ExternalSettingsError: profiles-retrieval-error: An error occurred while retrieving profiles from the server. - Inner Exception: HTTPSConnectionPool(host='raw.githubusercontent.com', port=443): Max retries exceeded with url: /FormerLurker/Octolapse-Profiles/master/versions.json?nonce=2377b8fbc7394ae3ac074fa919df07f4 (Caused by NewConnectionError('<urllib3.connection.HTTPSConnection object at 0x69c937b0>: Failed to establish a new connection: [Errno -3] Temporary failure in name resolution'))
